<?xml version='1.0' encoding='utf-8'?>
<robot name="my_urdf"><link name="base_link"><visual><origin xyz="0 0 0" rpy="0.0 0.0 0.0" /><material name="white"><color rgba="0.8 0.8 0.8 1" /></material><geometry><mesh filename="../meshes/cabinet.obj" scale="1 1 1" /></geometry></visual><collision><origin xyz="0 0 0" rpy="0.0 0.0 0.0" /><geometry><mesh filename="../meshes/cabinet.obj" scale="1 1 1" /></geometry></collision><inertial><mass value="1" /><inertia ixx="1e-4" ixy="0" ixz="0" iyy="1e-4" iyz="0" izz="1e-4" /></inertial></link><link name="doorR0"><visual><origin xyz="0 0 0" rpy="0 0 0" /><material name="white"><color rgba="0.8 0.8 0.8 1" /></material><geometry><mesh filename="../meshes/parts/doorR.obj" scale="1 3.99 1.99" /></geometry></visual><collision><origin xyz="0 0 0" rpy="0 0 0" /><geometry><mesh filename="../meshes/parts/doorR.obj" scale="1 3.99 1.99" /></geometry></collision><inertial><mass value="0.2" /><inertia ixx="1e-4" ixy="0" ixz="0" iyy="1e-4" iyz="0" izz="1e-4" /></inertial></link><joint name="doorR0_to_base_link" type="revolute"><axis xyz="0 0 1" /><limit effort="5" lower="0" upper="1.57" velocity="2.283" /><origin xyz="0 1.0 0.0" rpy="-0.0 -0.0 -0.0" /><parent link="base_link" /><child link="doorR0" /></joint><link name="doorR1"><visual><origin xyz="0 0 0" rpy="0 0 0" /><material name="white"><color rgba="0.8 0.8 0.8 1" /></material><geometry><mesh filename="../meshes/parts/doorR.obj" scale="1 3.99 1.99" /></geometry></visual><collision><origin xyz="0 0 0" rpy="0 0 0" /><geometry><mesh filename="../meshes/parts/doorR.obj" scale="1 3.99 1.99" /></geometry></collision><inertial><mass value="0.2" /><inertia ixx="1e-4" ixy="0" ixz="0" iyy="1e-4" iyz="0" izz="1e-4" /></inertial></link><joint name="doorR1_to_base_link" type="revolute"><axis xyz="0 0 1" /><limit effort="5" lower="0" upper="1.57" velocity="2.283" /><origin xyz="0 1.0 0.5" rpy="-0.0 -0.0 -0.0" /><parent link="base_link" /><child link="doorR1" /></joint><link name="knob2"><visual><origin xyz="0 0 0" rpy="0 0 0" /><material name="white"><color rgba="0.8 0.8 0.8 1" /></material><geometry><mesh filename="../meshes/parts/knob.obj" scale="1 1 1" /></geometry></visual><collision><origin xyz="0 0 0" rpy="0 0 0" /><geometry><mesh filename="../meshes/parts/knob.obj" scale="1 1 1" /></geometry></collision><inertial><mass value="0.2" /><inertia ixx="1e-4" ixy="0" ixz="0" iyy="1e-4" iyz="0" izz="1e-4" /></inertial></link><joint name="knob2_to_doorR0" type="fixed"><axis xyz="1 0 0" /><limit effort="5" lower="0" upper="1.57" velocity="2.283" /><origin xyz="0 -0.8333333333333334 0.25" rpy="0.0 0.0 0.0" /><parent link="doorR0" /><child link="knob2" /></joint><link name="knob3"><visual><origin xyz="0 0 0" rpy="0 0 0" /><material name="white"><color rgba="0.8 0.8 0.8 1" /></material><geometry><mesh filename="../meshes/parts/knob.obj" scale="1 1 1" /></geometry></visual><collision><origin xyz="0 0 0" rpy="0 0 0" /><geometry><mesh filename="../meshes/parts/knob.obj" scale="1 1 1" /></geometry></collision><inertial><mass value="0.2" /><inertia ixx="1e-4" ixy="0" ixz="0" iyy="1e-4" iyz="0" izz="1e-4" /></inertial></link><joint name="knob3_to_doorR1" type="fixed"><axis xyz="1 0 0" /><limit effort="5" lower="0" upper="1.57" velocity="2.283" /><origin xyz="0 -0.8333333333333334 0.25" rpy="0.0 0.0 0.0" /><parent link="doorR1" /><child link="knob3" /></joint></robot>