<?xml version='1.0' encoding='utf-8'?>
<robot name="my_urdf"><link name="base_link"><visual><origin xyz="0 0 0" rpy="0.0 0.0 0.0" /><material name="white"><color rgba="0.8 0.8 0.8 1" /></material><geometry><mesh filename="../meshes/cabinet.obj" scale="1 1 1" /></geometry></visual><collision><origin xyz="0 0 0" rpy="0.0 0.0 0.0" /><geometry><mesh filename="../meshes/cabinet.obj" scale="1 1 1" /></geometry></collision><inertial><mass value="1" /><inertia ixx="1e-4" ixy="0" ixz="0" iyy="1e-4" iyz="0" izz="1e-4" /></inertial></link><link name="drawer0"><visual><origin xyz="0 0 0" rpy="0 0 0" /><material name="white"><color rgba="0.8 0.8 0.8 1" /></material><geometry><mesh filename="../meshes/parts/drawer.obj" scale="1 0.98 0.98" /></geometry></visual><collision><origin xyz="0 0 0" rpy="0 0 0" /><geometry><mesh filename="../meshes/parts/drawer.obj" scale="1 0.98 0.98" /></geometry></collision><inertial><mass value="0.2" /><inertia ixx="1e-4" ixy="0" ixz="0" iyy="1e-4" iyz="0" izz="1e-4" /></inertial></link><joint name="drawer0_to_base_link" type="prismatic"><axis xyz="1 0 0" /><limit effort="5" lower="0" upper="0.4" velocity="2.283" /><origin xyz="0 0.0 0.75" rpy="0.0 0.0 0.0" /><parent link="base_link" /><child link="drawer0" /></joint><link name="drawer1"><visual><origin xyz="0 0 0" rpy="0 0 0" /><material name="white"><color rgba="0.8 0.8 0.8 1" /></material><geometry><mesh filename="../meshes/parts/drawer.obj" scale="1 1.98 0.98" /></geometry></visual><collision><origin xyz="0 0 0" rpy="0 0 0" /><geometry><mesh filename="../meshes/parts/drawer.obj" scale="1 1.98 0.98" /></geometry></collision><inertial><mass value="0.2" /><inertia ixx="1e-4" ixy="0" ixz="0" iyy="1e-4" iyz="0" izz="1e-4" /></inertial></link><joint name="drawer1_to_base_link" type="prismatic"><axis xyz="1 0 0" /><limit effort="5" lower="0" upper="0.4" velocity="2.283" /><origin xyz="0 0.5 0.0" rpy="0.0 0.0 0.0" /><parent link="base_link" /><child link="drawer1" /></joint><link name="doorR2"><visual><origin xyz="0 0 0" rpy="0 0 0" /><material name="white"><color rgba="0.8 0.8 0.8 1" /></material><geometry><mesh filename="../meshes/parts/doorR.obj" scale="1 1.3233333333333333 1.6566666666666667" /></geometry></visual><collision><origin xyz="0 0 0" rpy="0 0 0" /><geometry><mesh filename="../meshes/parts/doorR.obj" scale="1 1.3233333333333333 1.6566666666666667" /></geometry></collision><inertial><mass value="0.2" /><inertia ixx="1e-4" ixy="0" ixz="0" iyy="1e-4" iyz="0" izz="1e-4" /></inertial></link><joint name="doorR2_to_base_link" type="revolute"><axis xyz="0 0 1" /><limit effort="5" lower="0" upper="1.57" velocity="2.283" /><origin xyz="0 1.0 0.25" rpy="-0.0 -0.0 -0.0" /><parent link="base_link" /><child link="doorR2" /></joint><link name="drawer3"><visual><origin xyz="0 0 0" rpy="0 0 0" /><material name="white"><color rgba="0.8 0.8 0.8 1" /></material><geometry><mesh filename="../meshes/parts/drawer.obj" scale="1 1.98 0.98" /></geometry></visual><collision><origin xyz="0 0 0" rpy="0 0 0" /><geometry><mesh filename="../meshes/parts/drawer.obj" scale="1 1.98 0.98" /></geometry></collision><inertial><mass value="0.2" /><inertia ixx="1e-4" ixy="0" ixz="0" iyy="1e-4" iyz="0" izz="1e-4" /></inertial></link><joint name="drawer3_to_base_link" type="prismatic"><axis xyz="1 0 0" /><limit effort="5" lower="0" upper="0.4" velocity="2.283" /><origin xyz="0 0.0 0.0" rpy="0.0 0.0 0.0" /><parent link="base_link" /><child link="drawer3" /></joint><link name="drawer4"><visual><origin xyz="0 0 0" rpy="0 0 0" /><material name="white"><color rgba="0.8 0.8 0.8 1" /></material><geometry><mesh filename="../meshes/parts/drawer.obj" scale="1 0.6466666666666666 1.98" /></geometry></visual><collision><origin xyz="0 0 0" rpy="0 0 0" /><geometry><mesh filename="../meshes/parts/drawer.obj" scale="1 0.6466666666666666 1.98" /></geometry></collision><inertial><mass value="0.2" /><inertia ixx="1e-4" ixy="0" ixz="0" iyy="1e-4" iyz="0" izz="1e-4" /></inertial></link><joint name="drawer4_to_base_link" type="prismatic"><axis xyz="1 0 0" /><limit effort="5" lower="0" upper="0.4" velocity="2.283" /><origin xyz="0 0.25 0.25" rpy="0.0 0.0 0.0" /><parent link="base_link" /><child link="drawer4" /></joint><link name="drawer5"><visual><origin xyz="0 0 0" rpy="0 0 0" /><material name="white"><color rgba="0.8 0.8 0.8 1" /></material><geometry><mesh filename="../meshes/parts/drawer.obj" scale="1 0.6466666666666666 0.98" /></geometry></visual><collision><origin xyz="0 0 0" rpy="0 0 0" /><geometry><mesh filename="../meshes/parts/drawer.obj" scale="1 0.6466666666666666 0.98" /></geometry></collision><inertial><mass value="0.2" /><inertia ixx="1e-4" ixy="0" ixz="0" iyy="1e-4" iyz="0" izz="1e-4" /></inertial></link><joint name="drawer5_to_base_link" type="prismatic"><axis xyz="1 0 0" /><limit effort="5" lower="0" upper="0.4" velocity="2.283" /><origin xyz="0 0.0 0.5" rpy="0.0 0.0 0.0" /><parent link="base_link" /><child link="drawer5" /></joint><link name="drawer6"><visual><origin xyz="0 0 0" rpy="0 0 0" /><material name="white"><color rgba="0.8 0.8 0.8 1" /></material><geometry><mesh filename="../meshes/parts/drawer.obj" scale="1 1.3133333333333332 0.98" /></geometry></visual><collision><origin xyz="0 0 0" rpy="0 0 0" /><geometry><mesh filename="../meshes/parts/drawer.obj" scale="1 1.3133333333333332 0.98" /></geometry></collision><inertial><mass value="0.2" /><inertia ixx="1e-4" ixy="0" ixz="0" iyy="1e-4" iyz="0" izz="1e-4" /></inertial></link><joint name="drawer6_to_base_link" type="prismatic"><axis xyz="1 0 0" /><limit effort="5" lower="0" upper="0.4" velocity="2.283" /><origin xyz="0 0.0 0.25" rpy="0.0 0.0 0.0" /><parent link="base_link" /><child link="drawer6" /></joint><link name="drawer7"><visual><origin xyz="0 0 0" rpy="0 0 0" /><material name="white"><color rgba="0.8 0.8 0.8 1" /></material><geometry><mesh filename="../meshes/parts/drawer.obj" scale="1 2.3133333333333335 1.6466666666666667" /></geometry></visual><collision><origin xyz="0 0 0" rpy="0 0 0" /><geometry><mesh filename="../meshes/parts/drawer.obj" scale="1 2.3133333333333335 1.6466666666666667" /></geometry></collision><inertial><mass value="0.2" /><inertia ixx="1e-4" ixy="0" ixz="0" iyy="1e-4" iyz="0" izz="1e-4" /></inertial></link><joint name="drawer7_to_base_link" type="prismatic"><axis xyz="1 0 0" /><limit effort="5" lower="0" upper="0.4" velocity="2.283" /><origin xyz="0 0.4166666666666667 0.25" rpy="0.0 0.0 0.0" /><parent link="base_link" /><child link="drawer7" /></joint><link name="drawer8"><visual><origin xyz="0 0 0" rpy="0 0 0" /><material name="white"><color rgba="0.8 0.8 0.8 1" /></material><geometry><mesh filename="../meshes/parts/drawer.obj" scale="1 1.3133333333333332 0.98" /></geometry></visual><collision><origin xyz="0 0 0" rpy="0 0 0" /><geometry><mesh filename="../meshes/parts/drawer.obj" scale="1 1.3133333333333332 0.98" /></geometry></collision><inertial><mass value="0.2" /><inertia ixx="1e-4" ixy="0" ixz="0" iyy="1e-4" iyz="0" izz="1e-4" /></inertial></link><joint name="drawer8_to_base_link" type="prismatic"><axis xyz="1 0 0" /><limit effort="5" lower="0" upper="0.4" velocity="2.283" /><origin xyz="0 0.3333333333333333 0.25" rpy="0.0 0.0 0.0" /><parent link="base_link" /><child link="drawer8" /></joint><link name="drawer9"><visual><origin xyz="0 0 0" rpy="0 0 0" /><material name="white"><color rgba="0.8 0.8 0.8 1" /></material><geometry><mesh filename="../meshes/parts/drawer.obj" scale="1 1.6466666666666667 0.98" /></geometry></visual><collision><origin xyz="0 0 0" rpy="0 0 0" /><geometry><mesh filename="../meshes/parts/drawer.obj" scale="1 1.6466666666666667 0.98" /></geometry></collision><inertial><mass value="0.2" /><inertia ixx="1e-4" ixy="0" ixz="0" iyy="1e-4" iyz="0" izz="1e-4" /></inertial></link><joint name="drawer9_to_base_link" type="prismatic"><axis xyz="1 0 0" /><limit effort="5" lower="0" upper="0.4" velocity="2.283" /><origin xyz="0 0.25 0.75" rpy="0.0 0.0 0.0" /><parent link="base_link" /><child link="drawer9" /></joint><link name="drawer10"><visual><origin xyz="0 0 0" rpy="0 0 0" /><material name="white"><color rgba="0.8 0.8 0.8 1" /></material><geometry><mesh filename="../meshes/parts/drawer.obj" scale="1 1.3133333333333332 1.3133333333333332" /></geometry></visual><collision><origin xyz="0 0 0" rpy="0 0 0" /><geometry><mesh filename="../meshes/parts/drawer.obj" scale="1 1.3133333333333332 1.3133333333333332" /></geometry></collision><inertial><mass value="0.2" /><inertia ixx="1e-4" ixy="0" ixz="0" iyy="1e-4" iyz="0" izz="1e-4" /></inertial></link><joint name="drawer10_to_base_link" type="prismatic"><axis xyz="1 0 0" /><limit effort="5" lower="0" upper="0.4" velocity="2.283" /><origin xyz="0 0.6666666666666666 0.6666666666666666" rpy="0.0 0.0 0.0" /><parent link="base_link" /><child link="drawer10" /></joint><link name="knob11"><visual><origin xyz="0 0 0" rpy="0 0 0" /><material name="white"><color rgba="0.8 0.8 0.8 1" /></material><geometry><mesh filename="../meshes/parts/knob.obj" scale="1 1 1" /></geometry></visual><collision><origin xyz="0 0 0" rpy="0 0 0" /><geometry><mesh filename="../meshes/parts/knob.obj" scale="1 1 1" /></geometry></collision><inertial><mass value="0.2" /><inertia ixx="1e-4" ixy="0" ixz="0" iyy="1e-4" iyz="0" izz="1e-4" /></inertial></link><joint name="knob11_to_drawer0" type="fixed"><axis xyz="0 0 1" /><limit effort="5" lower="0" upper="0.4" velocity="2.283" /><origin xyz="0 0.125 0.125" rpy="1.5707963267948963 0.0 0.0" /><parent link="drawer0" /><child link="knob11" /></joint><link name="knob12"><visual><origin xyz="0 0 0" rpy="0 0 0" /><material name="white"><color rgba="0.8 0.8 0.8 1" /></material><geometry><mesh filename="../meshes/parts/knob.obj" scale="1 1 1" /></geometry></visual><collision><origin xyz="0 0 0" rpy="0 0 0" /><geometry><mesh filename="../meshes/parts/knob.obj" scale="1 1 1" /></geometry></collision><inertial><mass value="0.2" /><inertia ixx="1e-4" ixy="0" ixz="0" iyy="1e-4" iyz="0" izz="1e-4" /></inertial></link><joint name="knob12_to_drawer8" type="fixed"><axis xyz="0 0 1" /><limit effort="5" lower="0" upper="0.4" velocity="2.283" /><origin xyz="0 0.16666666666666666 0.125" rpy="1.5707963267948963 0.0 0.0" /><parent link="drawer8" /><child link="knob12" /></joint><link name="knob13"><visual><origin xyz="0 0 0" rpy="0 0 0" /><material name="white"><color rgba="0.8 0.8 0.8 1" /></material><geometry><mesh filename="../meshes/parts/knob.obj" scale="1 1 1" /></geometry></visual><collision><origin xyz="0 0 0" rpy="0 0 0" /><geometry><mesh filename="../meshes/parts/knob.obj" scale="1 1 1" /></geometry></collision><inertial><mass value="0.2" /><inertia ixx="1e-4" ixy="0" ixz="0" iyy="1e-4" iyz="0" izz="1e-4" /></inertial></link><joint name="knob13_to_drawer6" type="fixed"><axis xyz="0 0 1" /><limit effort="5" lower="0" upper="0.4" velocity="2.283" /><origin xyz="0 0.16666666666666666 0.125" rpy="1.5707963267948963 0.0 0.0" /><parent link="drawer6" /><child link="knob13" /></joint><link name="drawer14"><visual><origin xyz="0 0 0" rpy="0 0 0" /><material name="white"><color rgba="0.8 0.8 0.8 1" /></material><geometry><mesh filename="../meshes/parts/drawer.obj" scale="1 -0.02 -0.02" /></geometry></visual><collision><origin xyz="0 0 0" rpy="0 0 0" /><geometry><mesh filename="../meshes/parts/drawer.obj" scale="1 -0.02 -0.02" /></geometry></collision><inertial><mass value="0.2" /><inertia ixx="1e-4" ixy="0" ixz="0" iyy="1e-4" iyz="0" izz="1e-4" /></inertial></link><joint name="drawer14_to_drawer5" type="prismatic"><axis xyz="1 0 0" /><limit effort="5" lower="0" upper="0.4" velocity="2.283" /><origin xyz="0 0.5 0.8333333333333334" rpy="0.0 0.0 0.0" /><parent link="drawer5" /><child link="drawer14" /></joint><link name="knob15"><visual><origin xyz="0 0 0" rpy="0 0 0" /><material name="white"><color rgba="0.8 0.8 0.8 1" /></material><geometry><mesh filename="../meshes/parts/knob.obj" scale="1 1 1" /></geometry></visual><collision><origin xyz="0 0 0" rpy="0 0 0" /><geometry><mesh filename="../meshes/parts/knob.obj" scale="1 1 1" /></geometry></collision><inertial><mass value="0.2" /><inertia ixx="1e-4" ixy="0" ixz="0" iyy="1e-4" iyz="0" izz="1e-4" /></inertial></link><joint name="knob15_to_drawer4" type="fixed"><axis xyz="0 0 1" /><limit effort="5" lower="0" upper="0.4" velocity="2.283" /><origin xyz="0 0.08333333333333333 0.25" rpy="1.5707963267948963 0.0 0.0" /><parent link="drawer4" /><child link="knob15" /></joint><link name="knob16"><visual><origin xyz="0 0 0" rpy="0 0 0" /><material name="white"><color rgba="0.8 0.8 0.8 1" /></material><geometry><mesh filename="../meshes/parts/knob.obj" scale="1 1 1" /></geometry></visual><collision><origin xyz="0 0 0" rpy="0 0 0" /><geometry><mesh filename="../meshes/parts/knob.obj" scale="1 1 1" /></geometry></collision><inertial><mass value="0.2" /><inertia ixx="1e-4" ixy="0" ixz="0" iyy="1e-4" iyz="0" izz="1e-4" /></inertial></link><joint name="knob16_to_drawer3" type="fixed"><axis xyz="0 0 1" /><limit effort="5" lower="0" upper="0.4" velocity="2.283" /><origin xyz="0 0.25 0.125" rpy="1.5707963267948963 0.0 0.0" /><parent link="drawer3" /><child link="knob16" /></joint><link name="knob17"><visual><origin xyz="0 0 0" rpy="0 0 0" /><material name="white"><color rgba="0.8 0.8 0.8 1" /></material><geometry><mesh filename="../meshes/parts/knob.obj" scale="1 1 1" /></geometry></visual><collision><origin xyz="0 0 0" rpy="0 0 0" /><geometry><mesh filename="../meshes/parts/knob.obj" scale="1 1 1" /></geometry></collision><inertial><mass value="0.2" /><inertia ixx="1e-4" ixy="0" ixz="0" iyy="1e-4" iyz="0" izz="1e-4" /></inertial></link><joint name="knob17_to_doorR2" type="fixed"><axis xyz="1 0 0" /><limit effort="5" lower="0" upper="0.4" velocity="2.283" /><origin xyz="0 -0.2777777777777778 0.34722222222222227" rpy="0.0 0.0 0.0" /><parent link="doorR2" /><child link="knob17" /></joint><link name="knob18"><visual><origin xyz="0 0 0" rpy="0 0 0" /><material name="white"><color rgba="0.8 0.8 0.8 1" /></material><geometry><mesh filename="../meshes/parts/knob.obj" scale="1 1 1" /></geometry></visual><collision><origin xyz="0 0 0" rpy="0 0 0" /><geometry><mesh filename="../meshes/parts/knob.obj" scale="1 1 1" /></geometry></collision><inertial><mass value="0.2" /><inertia ixx="1e-4" ixy="0" ixz="0" iyy="1e-4" iyz="0" izz="1e-4" /></inertial></link><joint name="knob18_to_drawer1" type="fixed"><axis xyz="0 0 1" /><limit effort="5" lower="0" upper="0.4" velocity="2.283" /><origin xyz="0 0.25 0.125" rpy="1.5707963267948963 0.0 0.0" /><parent link="drawer1" /><child link="knob18" /></joint><link name="knob19"><visual><origin xyz="0 0 0" rpy="0 0 0" /><material name="white"><color rgba="0.8 0.8 0.8 1" /></material><geometry><mesh filename="../meshes/parts/knob.obj" scale="1 1 1" /></geometry></visual><collision><origin xyz="0 0 0" rpy="0 0 0" /><geometry><mesh filename="../meshes/parts/knob.obj" scale="1 1 1" /></geometry></collision><inertial><mass value="0.2" /><inertia ixx="1e-4" ixy="0" ixz="0" iyy="1e-4" iyz="0" izz="1e-4" /></inertial></link><joint name="knob19_to_drawer9" type="fixed"><axis xyz="0 0 1" /><limit effort="5" lower="0" upper="0.4" velocity="2.283" /><origin xyz="0 0.20833333333333334 0.125" rpy="1.5707963267948963 0.0 0.0" /><parent link="drawer9" /><child link="knob19" /></joint><link name="knob20"><visual><origin xyz="0 0 0" rpy="0 0 0" /><material name="white"><color rgba="0.8 0.8 0.8 1" /></material><geometry><mesh filename="../meshes/parts/knob.obj" scale="1 1 1" /></geometry></visual><collision><origin xyz="0 0 0" rpy="0 0 0" /><geometry><mesh filename="../meshes/parts/knob.obj" scale="1 1 1" /></geometry></collision><inertial><mass value="0.2" /><inertia ixx="1e-4" ixy="0" ixz="0" iyy="1e-4" iyz="0" izz="1e-4" /></inertial></link><joint name="knob20_to_drawer10" type="fixed"><axis xyz="0 0 1" /><limit effort="5" lower="0" upper="0.4" velocity="2.283" /><origin xyz="0 0.16666666666666666 0.16666666666666666" rpy="1.5707963267948963 0.0 0.0" /><parent link="drawer10" /><child link="knob20" /></joint></robot>